Workbook

Sheet Cover
B2: TalentPact
B3: Financial Model — 36 Months (2026–2028)
B5: Empresa | C5: TalentPact
B6: Website | C6: talentpact.es
B7: Horizonte | C7: 36 meses (Ene 2026 – Dic 2028)
B8: Divisa | C8: EUR (€)
B9: Escenario | C9: Base Case
B10: Última actualización | C10: 17/04/2026 (corregido)
B11: Fundadores | C11: Iván Sánchez · Xavier Griñó
B13: Corrección | C13: Balance reconstruido · Cashflow corregido (+equity/+ENISA) · P&L corregido · Nueva hoja Análisis
B16: Leyenda de Colores
B17: Azul | C17: Inputs / Supuestos editables
B18: Negro | C18: Fórmulas y cálculos
B19: Verde | C19: Referencias a otras pestañas
B20: Rojo | C20: Valores negativos / alertas
B21: Amarillo (fondo) | C21: Celdas clave de supuestos

Sheet Análisis
B1: TALENTPACT — ANÁLISIS FINANCIERO
B2: Break-even · Burn Rate · Runway · Ratios clave
B4: 1. BURN RATE (Ritmo mensual de consumo de caja)
B5: Métrica | C5: 2026 | D5: 2027 | E5: 2028 | G5: Descripción
B6: Gross Burn (Salidas de caja/mes) | C6: =(-'P&L'!AN8+'P&L'!AN15*-1)/12 -> 6568.6595 | D6: =(-'P&L'!AO8+'P&L'!AO15*-1)/12 -> 16262.168 | E6: =(-'P&L'!AP8+'P&L'!AP15*-1)/12 -> 26254.73 | G6: COGS + SG&A / 12
B7: Net Burn (EBITDA negativo/mes) | C7: =IF('P&L'!AN17<0,-'P&L'!AN17/12,0) -> 5210.0577 | D7: =IF('P&L'!AO17<0,-'P&L'!AO17/12,0) -> 7199.6416 | E7: =IF('P&L'!AP17<0,-'P&L'!AP17/12,0) -> 0 | G7: EBITDA negativo / 12 (pérdida operativa media)
B8: Cash Burn medio (variación caja/mes) | C8: =Cashflow!AN27/12 -> 13394.109 | D8: =Cashflow!AO27/12 -> -8118.1094 | E8: =Cashflow!AP27/12 -> 845.47625 | G8: Variación neta anual / 12 (incluye equity + ENISA + capex)
B10: 2. RUNWAY (Meses de caja disponible)
B11: Momento | C11: Caja € | D11: Net Burn €/mes | E11: Runway (meses) | G11: Descripción
B12: Inicio (Ene-26) con Pre-Seed 180k | C12: =Cashflow!C7 -> 180000 | D12: =-'P&L'!AN17/12 -> 5210.0577 | E12: =C12/D12 -> 34.548561 | G12: Runway con sólo Equity (sin ENISA) a burn 2026
B13: Inicio (Ene-26) con Pre-Seed + ENISA (230k) | C13: =Cashflow!C7+Cashflow!C8 -> 230000 | D13: =-'P&L'!AN17/12 -> 5210.0577 | E13: =C13/D13 -> 44.145384 | G13: Runway con toda la financiación a burn 2026 (best case)
B14: Fin 2026 (caja 160k) al burn 2027 | C14: =Cashflow!O29 -> 160729.31 | D14: =-'P&L'!AO17/12 -> 7199.6416 | E14: =C14/D14 -> 22.324626 | G14: Runway con caja a 31-Dic-26 al ritmo de burn 2027
B15: Fin 2027 (caja 63k) al burn 2028 (si neg.) | C15: =Cashflow!AA29 -> 63311.995 | D15: =MAX(-'P&L'!AP17/12,0.01) -> 0.01 | E15: =IF('P&L'!AP17>=0,"Cash-flow positivo",C15/D15) -> Cash-flow positivo | G15: Runway a 31-Dic-27. Si EBITDA>0, ya no quema caja
B17: 3. BREAK-EVEN (Punto de equilibrio)
B18: Indicador | C18: Valor | G18: Comentario
B19: Primer mes con EBITDA ≥ 0 | C19: 46874 | G19: Mes en que se alcanza break-even operativo mensual
B20: Primer mes con Net Income ≥ 0 | C20: 46874 | G20: Mes de break-even neto (después de intereses e impuestos)
B21: Revenue neto/mes para break-even oper. (a SG&A Dic-27) | C21: =-'P&L'!AA15/'P&L'!AA10 -> 18211.771 | G21: SG&A mensual Dic-27 ÷ Gross Margin %
B22: Revenue neto/mes para break-even oper. (a SG&A Dic-28) | C22: =-'P&L'!AM15/'P&L'!AM10 -> 27701.878 | G22: SG&A mensual Dic-28 ÷ Gross Margin %
B23: Empresas (B2B) necesarias para BE oper. a Dic-27 | C23: =('P&L'!AA15*-1/'P&L'!AA10)/('MODELO NORMAL'!AA39/'MODELO NORMAL'!AA27) -> 125.36482 | G23: Rev. BE ÷ ARPU blended (Dic-27)
B25: 4. CAJA MÍNIMA Y NECESIDADES DE FINANCIACIÓN
B26: Métrica | C26: Valor | G26: Detalle
B27: Caja mínima proyectada (valle) | C27: =MIN(Cashflow!D29:AM29) -> 38002.877 | G27: Punto más bajo en los 36 meses de horizonte
B28: Mes de caja mínima | C28: =INDEX('P&L'!$D$3:$AM$3,MATCH(MIN(Cashflow!D29:AM29),Cashflow!D29:AM29,0)) -> Apr 2028 | G28: Mes en que la caja toca fondo
B29: Capital total necesario (Equity + ENISA) | C29: =Cashflow!C7+Cashflow!C8 -> 230000 | G29: Fondos necesarios para mantener caja > 0 hasta break-even
B30: Pérdida acumulada hasta break-even | C30: ='P&L'!AN21+'P&L'!AO21 -> -153688.01 | G30: Pérdidas 2026 + 2027 (hasta que se vuelve rentable en 2028)
B32: 5. KPIs SaaS CLAVE
B33: Métrica | C33: 2026 | D33: 2027 | E33: 2028 | G33: Descripción
B34: ARR (Annualized Run Rate) Dic | C34: ='MODELO NORMAL'!O39*12 -> 41972.688 | D34: ='MODELO NORMAL'!AA39*12 -> 224878.25 | E34: ='MODELO NORMAL'!AM39*12 -> 496529.81 | G34: Revenue Diciembre × 12
B35: ARPU Blended B2B (€/empresa/mes) | C35: ='MODELO NORMAL'!O39/'MODELO NORMAL'!O27 -> 145.7385 | D35: ='MODELO NORMAL'!AA39/'MODELO NORMAL'!AA27 -> 145.27019 | E35: ='MODELO NORMAL'!AM39/'MODELO NORMAL'!AM27 -> 145.69537 | G35: Revenue mes Dic ÷ Empresas EOM Dic
B36: Gross Margin % | C36: ='P&L'!AN9/'P&L'!AN6 -> 0.93480344 | D36: ='P&L'!AO9/'P&L'!AO6 -> 0.93322304 | E36: ='P&L'!AP9/'P&L'!AP6 -> 0.93773939 | G36: Gross Profit / Net Revenue
B37: EBITDA Margin % | C37: ='P&L'!AN17/'P&L'!AN6 -> -3.8348675 | D37: ='P&L'!AO17/'P&L'!AO6 -> -0.7944409 | E37: ='P&L'!AP17/'P&L'!AP6 -> 0.12538633 | G37: EBITDA / Net Revenue
B38: CAC B2B (€/nueva empresa) | C38: ='COGS & SG&A'!AN45/SUM('MODELO NORMAL'!D24:O24) -> 237.55556 | D38: ='COGS & SG&A'!AO45/SUM('MODELO NORMAL'!P24:AA24) -> 195.38931 | E38: ='COGS & SG&A'!AP45/SUM('MODELO NORMAL'!AB24:AM24) -> 256.17155 | G38: Marketing total ÷ Nuevas empresas
B39: LTV B2B (Customer Lifetime Value) | C39: =('MODELO NORMAL'!O39/'MODELO NORMAL'!O27)*('P&L'!AN9/'P&L'!AN6)/'MODELO NORMAL'!O8 -> 2724.737 | D39: =('MODELO NORMAL'!AA39/'MODELO NORMAL'!AA27)*('P&L'!AO9/'P&L'!AO6)/'MODELO NORMAL'!AA8 -> 3389.2371 | E39: =('MODELO NORMAL'!AM39/'MODELO NORMAL'!AM27)*('P&L'!AP9/'P&L'!AP6)/'MODELO NORMAL'!AM8 -> 3903.551 | G39: ARPU × GM% ÷ churn mensual
B40: Ratio LTV / CAC (objetivo > 3x) | C40: =C39/C38 -> 11.469894 | D40: =D39/D38 -> 17.346072 | E40: =E39/E38 -> 15.238035 | G40: LTV ÷ CAC (sano si > 3x; excelente si > 5x)
B41: Payback CAC (meses) | C41: ='COGS & SG&A'!AN45/SUM('MODELO NORMAL'!D24:O24)/('MODELO NORMAL'!O39/'MODELO NORMAL'!O27*'P&L'!AN9/'P&L'!AN6) -> 1.7436953 | D41: ='COGS & SG&A'!AO45/SUM('MODELO NORMAL'!P24:AA24)/('MODELO NORMAL'!AA39/'MODELO NORMAL'!AA27*'P&L'!AO9/'P&L'!AO6) -> 1.4412485 | E41: ='COGS & SG&A'!AP45/SUM('MODELO NORMAL'!AB24:AM24)/('MODELO NORMAL'!AM39/'MODELO NORMAL'!AM27*'P&L'!AP9/'P&L'!AP6) -> 1.8750074 | G41: CAC ÷ (ARPU × GM%). Meses para recuperar el CAC

Sheet MODELO NORMAL
B1: TalentPact — Revenue Buildup (36 meses)
B2: TalentPact - Financial Model | C2: Units | D2: 2026 | E2: 2026 | F2: 2026 | G2: 2026 | H2: 2026 | I2: 2026 | J2: 2026 | K2: 2026 | L2: 2026 | M2: 2026 | N2: 2026 | O2: 2026 | P2: 2027 | Q2: 2027 | R2: 2027 | S2: 2027 | T2: 2027 | U2: 2027 | V2: 2027 | W2: 2027 | X2: 2027 | Y2: 2027 | Z2: 2027 | AA2: 2027 | AB2: 2028 | AC2: 2028 | AD2: 2028 | AE2: 2028 | AF2: 2028 | AG2: 2028 | AH2: 2028 | AI2: 2028 | AJ2: 2028 | AK2: 2028 | AL2: 2028 | AM2: 2028 | AN2: Total 2026 | AO2: Total 2027 | AP2: Total 2028
B3: Revenue Buildup | C3: Ref. | D3: Jan 2026 | E3: Feb 2026 | F3: Mar 2026 | G3: Apr 2026 | H3: May 2026 | I3: Jun 2026 | J3: Jul 2026 | K3: Aug 2026 | L3: Sep 2026 | M3: Oct 2026 | N3: Nov 2026 | O3: Dec 2026 | P3: Jan 2027 | Q3: Feb 2027 | R3: Mar 2027 | S3: Apr 2027 | T3: May 2027 | U3: Jun 2027 | V3: Jul 2027 | W3: Aug 2027 | X3: Sep 2027 | Y3: Oct 2027 | Z3: Nov 2027 | AA3: Dec 2027 | AB3: Jan 2028 | AC3: Feb 2028 | AD3: Mar 2028 | AE3: Apr 2028 | AF3: May 2028 | AG3: Jun 2028 | AH3: Jul 2028 | AI3: Aug 2028 | AJ3: Sep 2028 | AK3: Oct 2028 | AL3: Nov 2028 | AM3: Dec 2028 | AN3: Anual 2026 | AO3: Anual 2027 | AP3: Anual 2028
B4: CRECIMIENTO | C4: 1 | AQ4: EL % SE CAMBIA SEGUN EL VALOR SI, ES 1 ES MODO NORMAL SI CAMBIAMOS A 0,8 ES MODELO CONSERVADOR Y A 1,3 ES MODELO AGRESIVO
B5: SUPUESTOS / ASSUMPTIONS
B6: % crecimiento empresas nuevas lógico | D6: 0 | E6: 0 | F6: 0 | G6: 0.15 | H6: 0.15 | I6: 0.2 | J6: 0.2 | K6: 0.25 | L6: 0.25 | M6: 0.3 | N6: 0.3 | O6: 0.3 | P6: 0.15 | Q6: 0.15 | R6: 0.15 | S6: 0.18 | T6: 0.18 | U6: 0.18 | V6: 0.2 | W6: 0.2 | X6: 0.2 | Y6: 0.22 | Z6: 0.22 | AA6: 0.22 | AB6: 0.12 | AC6: 0.12 | AD6: 0.12 | AE6: 0.12 | AF6: 0.1 | AG6: 0.1 | AH6: 0.1 | AI6: 0.1 | AJ6: 0.1 | AK6: 0.1 | AL6: 0.08 | AM6: 0.08
B7: % crecimiento empresas nuevas (monthly adds) | D7: =D6*$C$4 -> 0 | E7: =E6*$C$4 -> 0 | F7: =F6*$C$4 -> 0 | G7: =G6*$C$4 -> 0.15 | H7: =H6*$C$4 -> 0.15 | I7: =I6*$C$4 -> 0.2 | J7: =J6*$C$4 -> 0.2 | K7: =K6*$C$4 -> 0.25 | ... AM7: =AM6*$C$4 -> 0.08
B8: % churn empresas suscripción (mensual) | D8: 0.05 | E8: 0.05 | F8: 0.05 | G8: 0.05 | H8: 0.05 | I8: 0.05 | J8: 0.05 | K8: 0.05 | L8: 0.05 | M8: 0.05 | N8: 0.05 | O8: 0.05 | P8: 0.04 | Q8: 0.04 | R8: 0.04 | S8: 0.04 | T8: 0.04 | U8: 0.04 | V8: 0.04 | W8: 0.04 | X8: 0.04 | Y8: 0.04 | Z8: 0.04 | AA8: 0.04 | AB8: 0.035 | AC8: 0.035 | AD8: 0.035 | AE8: 0.035 | AF8: 0.035 | AG8: 0.035 | AH8: 0.035 | AI8: 0.035 | AJ8: 0.035 | AK8: 0.035 | AL8: 0.035 | AM8: 0.035
B9: Precio: Individual pago único | C9: €/contacto | D9: 49 | E9: 49 | F9: 49 | G9: 49 | H9: 49 | I9: 49 | J9: 49 | K9: 49 | L9: 49 | M9: 49 | N9: 49 | O9: 49 | P9: 49 | Q9: 49 | R9: 49 | S9: 49 | T9: 49 | U9: 49 | V9: 49 | W9: 49 | X9: 49 | Y9: 49 | Z9: 49 | AA9: 49 | AB9: 49 | AC9: 49 | AD9: 49 | AE9: 49 | AF9: 49 | AG9: 49 | AH9: 49 | AI9: 49 | AJ9: 49 | AK9: 49 | AL9: 49 | AM9: 49
B10: Precio: Pro (€/mes, suscripción) | C10: €/mes | D10: 199 | E10: 199 | F10: 199 | G10: 199 | H10: 199 | I10: 199 | J10: 199 | K10: 199 | L10: 199 | M10: 199 | N10: 199 | O10: 199 | P10: 199 | Q10: 199 | R10: 199 | S10: 199 | T10: 199 | U10: 199 | V10: 199 | W10: 199 | X10: 199 | Y10: 199 | Z10: 199 | AA10: 199 | AB10: 199 | AC10: 199 | AD10: 199 | AE10: 199 | AF10: 199 | AG10: 199 | AH10: 199 | AI10: 199 | AJ10: 199 | AK10: 199 | AL10: 199 | AM10: 199
B11: Precio: Ejercicio personalizado | C11: €/mes | D11: 299 | E11: 299 | F11: 299 | G11: 299 | H11: 299 | I11: 299 | J11: 299 | K11: 299 | L11: 299 | M11: 299 | N11: 299 | O11: 299 | P11: 299 | Q11: 299 | R11: 299 | S11: 299 | T11: 299 | U11: 299 | V11: 299 | W11: 299 | X11: 299 | Y11: 299 | Z11: 299 | AA11: 299 | AB11: 299 | AC11: 299 | AD11: 299 | AE11: 299 | AF11: 299 | AG11: 299 | AH11: 299 | AI11: 299 | AJ11: 299 | AK11: 299 | AL11: 299 | AM11: 299
B12: Precio: Enterprise (€/mes, suscripción) | C12: €/mes | D12: 499 | E12: 499 | F12: 499 | G12: 499 | H12: 499 | I12: 499 | J12: 499 | K12: 499 | L12: 499 | M12: 499 | N12: 499 | O12: 499 | P12: 499 | Q12: 499 | R12: 499 | S12: 499 | T12: 499 | U12: 499 | V12: 499 | W12: 499 | X12: 499 | Y12: 499 | Z12: 499 | AA12: 499 | AB12: 499 | AC12: 499 | AD12: 499 | AE12: 499 | AF12: 499 | AG12: 499 | AH12: 499 | AI12: 499 | AJ12: 499 | AK12: 499 | AL12: 499 | AM12: 499
B13: Precio: B2C reto extra (€) | C13: €/reto | D13: 5 | E13: 5 | F13: 5 | G13: 5 | H13: 5 | I13: 5 | J13: 5 | K13: 5 | L13: 5 | M13: 5 | N13: 5 | O13: 5 | P13: 5 | Q13: 5 | R13: 5 | S13: 5 | T13: 5 | U13: 5 | V13: 5 | W13: 5 | X13: 5 | Y13: 5 | Z13: 5 | AA13: 5 | AB13: 5 | AC13: 5 | AD13: 5 | AE13: 5 | AF13: 5 | AG13: 5 | AH13: 5 | AI13: 5 | AJ13: 5 | AK13: 5 | AL13: 5 | AM13: 5
B14: Comisión pasarela de pago Stripe (%) | D14: 0.02 | E14: 0.02 | F14: 0.02 | G14: 0.02 | H14: 0.02 | I14: 0.02 | J14: 0.02 | K14: 0.02 | L14: 0.02 | M14: 0.02 | N14: 0.02 | O14: 0.02 | P14: 0.02 | Q14: 0.02 | R14: 0.02 | S14: 0.02 | T14: 0.02 | U14: 0.02 | V14: 0.02 | W14: 0.02 | X14: 0.02 | Y14: 0.02 | Z14: 0.02 | AA14: 0.02 | AB14: 0.02 | AC14: 0.02 | AD14: 0.02 | AE14: 0.02 | AF14: 0.02 | AG14: 0.02 | AH14: 0.02 | AI14: 0.02 | AJ14: 0.02 | AK14: 0.02 | AL14: 0.02 | AM14: 0.02
B15: % crecimiento candidatos lógico | D15: ='MODELO NORMAL'!G56 -> 0 | E15: 0.3 | F15: 0.3 | G15: 0.5 | H15: 0.5 | I15: 0.4 | J15: 0.35 | K15: 0.3 | L15: 0.25 | M15: 0.2 | N15: 0.2 | O15: 0.15 | P15: 0.15 | Q15: 0.15 | R15: 0.15 | S15: 0.2 | T15: 0.2 | U15: 0.15 | V15: 0.15 | W15: 0.12 | X15: 0.12 | Y15: 0.1 | Z15: 0.1 | AA15: 0.1 | AB15: 0.1 | AC15: 0.1 | AD15: 0.08 | AE15: 0.08 | AF15: 0.08 | AG15: 0.08 | AH15: 0.07 | AI15: 0.07 | AJ15: 0.07 | AK15: 0.07 | AL15: 0.06 | AM15: 0.06
B16: % crecimiento candidatos (mensual) | D16: =D15*$C$4 -> 0 | E16: =E15*$C$4 -> 0.3 | F16: =F15*$C$4 -> 0.3 | G16: =G15*$C$4 -> 0.5 | H16: =H15*$C$4 -> 0.5 | I16: =I15*$C$4 -> 0.4 | J16: =J15*$C$4 -> 0.35 | K16: =K15*$C$4 -> 0.3 | ... AM16: =AM15*$C$4 -> 0.06
B17: % candidatos que pagan B2C | D17: 0 | E17: 0 | F17: 0 | G17: 0 | H17: 0 | I17: 0 | J17: 0 | K17: 0.03 | L17: 0.03 | M17: 0.03 | N17: 0.03 | O17: 0.03 | P17: 0.03 | Q17: 0.03 | R17: 0.03 | S17: 0.03 | T17: 0.03 | U17: 0.03 | V17: 0.03 | W17: 0.03 | X17: 0.03 | Y17: 0.03 | Z17: 0.03 | AA17: 0.03 | AB17: 0.03 | AC17: 0.03 | AD17: 0.03 | AE17: 0.03 | AF17: 0.03 | AG17: 0.03 | AH17: 0.03 | AI17: 0.03 | AJ17: 0.03 | AK17: 0.03 | AL17: 0.03 | AM17: 0.03
B18: Media contactos/empresa Individual (mes) | D18: 1.2 | E18: 1.2 | F18: 1.2 | G18: 1.2 | H18: 1.2 | I18: 1.2 | J18: 1.2 | K18: 1.2 | L18: 1.2 | M18: 1.2 | N18: 1.2 | O18: 1.2 | P18: 1.2 | Q18: 1.2 | R18: 1.2 | S18: 1.2 | T18: 1.2 | U18: 1.2 | V18: 1.2 | W18: 1.2 | X18: 1.2 | Y18: 1.2 | Z18: 1.2 | AA18: 1.2 | AB18: 1.2 | AC18: 1.2 | AD18: 1.2 | AE18: 1.2 | AF18: 1.2 | AG18: 1.2 | AH18: 1.2 | AI18: 1.2 | AJ18: 1.2 | AK18: 1.2 | AL18: 1.2 | AM18: 1.2
B19: % empresas en plan Pro | D19: 0.25 | E19: 0.25 | F19: 0.25 | G19: 0.25 | H19: 0.25 | I19: 0.25 | J19: 0.25 | K19: 0.25 | L19: 0.25 | M19: 0.25 | N19: 0.25 | O19: 0.25 | P19: 0.25 | Q19: 0.25 | R19: 0.25 | S19: 0.25 | T19: 0.25 | U19: 0.25 | V19: 0.25 | W19: 0.25 | X19: 0.25 | Y19: 0.25 | Z19: 0.25 | AA19: 0.25 | AB19: 0.25 | AC19: 0.25 | AD19: 0.25 | AE19: 0.25 | AF19: 0.25 | AG19: 0.25 | AH19: 0.25 | AI19: 0.25 | AJ19: 0.25 | AK19: 0.25 | AL19: 0.25 | AM19: 0.25
B20: % empresas en plan Team (299€) | D20: 0.05 | E20: 0.05 | F20: 0.05 | G20: 0.05 | H20: 0.05 | I20: 0.05 | J20: 0.05 | K20: 0.05 | L20: 0.05 | M20: 0.05 | N20: 0.05 | O20: 0.05 | P20: 0.05 | Q20: 0.05 | R20: 0.05 | S20: 0.05 | T20: 0.05 | U20: 0.05 | V20: 0.05 | W20: 0.05 | X20: 0.05 | Y20: 0.05 | Z20: 0.05 | AA20: 0.05 | AB20: 0.05 | AC20: 0.05 | AD20: 0.05 | AE20: 0.05 | AF20: 0.05 | AG20: 0.05 | AH20: 0.05 | AI20: 0.05 | AJ20: 0.05 | AK20: 0.05 | AL20: 0.05 | AM20: 0.05
B21: % empresas en plan Enterprise | D21: 0.08 | E21: 0.08 | F21: 0.08 | G21: 0.08 | H21: 0.08 | I21: 0.08 | J21: 0.08 | K21: 0.08 | L21: 0.08 | M21: 0.08 | N21: 0.08 | O21: 0.08 | P21: 0.08 | Q21: 0.08 | R21: 0.08 | S21: 0.08 | T21: 0.08 | U21: 0.08 | V21: 0.08 | W21: 0.08 | X21: 0.08 | Y21: 0.08 | Z21: 0.08 | AA21: 0.08 | AB21: 0.08 | AC21: 0.08 | AD21: 0.08 | AE21: 0.08 | AF21: 0.08 | AG21: 0.08 | AH21: 0.08 | AI21: 0.08 | AJ21: 0.08 | AK21: 0.08 | AL21: 0.08 | AM21: 0.08
B22: EMPRESAS (B2B) — Evolución de clientes
B23: Empresas (inicio de mes, BOM) | D23: 1 | E23: =D27 -> 2 | F23: =E27 -> 3 | G23: =F27 -> 4 | H23: =G27 -> 5 | I23: =H27 -> 6 | J23: =I27 -> 7 | K23: =J27 -> 8 | L23: =K27 -> 10 | ... AM23: =AL27 -> 271
B24: Nuevas empresas | D24: 1 | E24: =MAX(1,ROUND(E23*E7,0)) -> 1 | F24: =MAX(1,ROUND(F23*F7,0)) -> 1 | G24: =MAX(1,ROUND(G23*G7,0)) -> 1 | H24: =MAX(1,ROUND(H23*H7,0)) -> 1 | I24: =MAX(1,ROUND(I23*I7,0)) -> 1 | J24: =MAX(1,ROUND(J23*J7,0)) -> 1 | K24: =MAX(1,ROUND(K23*K7,0)) -> 2 | L24: =MAX(1,ROUND(L23*L7,0)) -> 3 | ... AM24: =MAX(1,ROUND(AM23*AM7,0)) -> 22
B25: Bajas (churn) | D25: =-ROUND(D23*D8,0) -> 0 | E25: =-ROUND(E23*E8,0) -> 0 | F25: =-ROUND(F23*F8,0) -> 0 | G25: =-ROUND(G23*G8,0) -> 0 | H25: =-ROUND(H23*H8,0) -> 0 | I25: =-ROUND(I23*I8,0) -> 0 | J25: =-ROUND(J23*J8,0) -> 0 | K25: =-ROUND(K23*K8,0) -> 0 | ... AM25: =-ROUND(AM23*AM8,0) -> -9
B26: Neto de altas | D26: =D24+D25 -> 1 | E26: =E24+E25 -> 1 | F26: =F24+F25 -> 1 | G26: =G24+G25 -> 1 | H26: =H24+H25 -> 1 | I26: =I24+I25 -> 1 | J26: =J24+J25 -> 1 | K26: =K24+K25 -> 2 | ... AM26: =AM24+AM25 -> 13
B27: Empresas (fin de mes, EOM) | D27: =D23+D26 -> 2 | E27: =E23+E26 -> 3 | F27: =F23+F26 -> 4 | G27: =G23+G26 -> 5 | H27: =H23+H26 -> 6 | I27: =I23+I26 -> 7 | J27: =J23+J26 -> 8 | K27: =K23+K26 -> 10 | ... AM27: =AM23+AM26 -> 284 | AN27: =O27 -> 24 | AO27: =AA27 -> 129 | AP27: =AM27 -> 284
B28: MoM crecimiento % | D28: =IF(C27>0,(D27-C27)/C27,"N/A") -> N/A | E28: =IF(D27>0,(E27-D27)/D27,"N/A") -> 0.5 | F28: =IF(E27>0,(F27-E27)/E27,"N/A") -> 0.33333333 | G28: =IF(F27>0,(G27-F27)/F27,"N/A") -> 0.25 | H28: =IF(G27>0,(H27-G27)/G27,"N/A") -> 0.2 | I28: =IF(H27>0,(I27-H27)/H27,"N/A") -> 0.16666667 | J28: =IF(I27>0,(J27-I27)/I27,"N/A") -> 0.14285714 | K28: =IF(J27>0,(K27-J27)/J27,"N/A") -> 0.25 | ... AM28: =IF(AL27>0,(AM27-AL27)/AL27,"N/A") -> 0.04797048
B29: CANDIDATOS (B2C) — Evolución de usuarios
B30: Candidatos (inicio de mes, BOM) | D30: 20 | E30: =D32 -> 30 | F30: =E32 -> 50 | G30: =F32 -> 65 | H30: =G32 -> 98 | I30: =H32 -> 147 | J30: =I32 -> 206 | K30: =J32 -> 278 | L30: =K32 -> 361 | ... AM30: =AL32 -> 8251
B31: Nuevos candidatos | D31: 10 | E31: 20 | F31: =ROUND(F30*F16,0) -> 15 | G31: =ROUND(G30*G16,0) -> 33 | H31: =ROUND(H30*H16,0) -> 49 | I31: =ROUND(I30*I16,0) -> 59 | J31: =ROUND(J30*J16,0) -> 72 | K31: =ROUND(K30*K16,0) -> 83 | L31: =ROUND(L30*L16,0) -> 90 | M31: =ROUND(M30*M16,0) -> 90 | ... AM31: =ROUND(AM30*AM16,0) -> 495
B32: Candidatos (fin de mes, EOM) | D32: =D30+D31 -> 30 | E32: =E30+E31 -> 50 | F32: =F30+F31 -> 65 | G32: =G30+G31 -> 98 | H32: =H30+H31 -> 147 | I32: =I30+I31 -> 206 | J32: =J30+J31 -> 278 | K32: =K30+K31 -> 361 | ... AM32: =AM30+AM31 -> 8746 | AN32: =O32 -> 746 | AO32: =AA32 -> 3607 | AP32: =AM32 -> 8746
B33: INGRESOS BRUTOS — Revenue Buildup (€)
B34: Individual (€49/contacto, pago único) | D34: =(1-D19-D20-D21)*D27*D18*D9 -> 72.912 | E34: =(1-E19-E20-E21)*E27*E18*E9 -> 109.368 | F34: =(1-F19-F20-F21)*F27*F18*F9 -> 145.824 | G34: =(1-G19-G20-G21)*G27*G18*G9 -> 182.28 | H34: =(1-H19-H20-H21)*H27*H18*H9 -> 218.736 | I34: =(1-I19-I20-I21)*I27*I18*I9 -> 255.192 | J34: =(1-J19-J20-J21)*J27*J18*J9 -> 291.648 | K34: =(1-K19-K20-K21)*K27*K18*K9 -> 364.56 | ... AM34: =(1-AM19-AM20-AM21)*AM27*AM18*AM9 -> 10353.504 | AN34: =SUM(D34:O34) -> 4192.44 | AO34: =SUM(P34:AA34) -> 27706.56 | AP34: =SUM(AB34:AM34) -> 92087.856
B35: Pro (€199/mes) | D35: =D19*D27*D10 -> 99.5 | E35: =E19*E27*E10 -> 149.25 | F35: =F19*F27*F10 -> 199 | G35: =G19*G27*G10 -> 248.75 | H35: =H19*H27*H10 -> 298.5 | I35: =I19*I27*I10 -> 348.25 | J35: =J19*J27*J10 -> 398 | K35: =K19*K27*K10 -> 497.5 | ... AM35: =AM19*AM27*AM10 -> 14129 | AN35: =SUM(D35:O35) -> 5721.25 | AO35: =SUM(P35:AA35) -> 37810 | AP35: =SUM(AB35:AM35) -> 125668.5
B36: Ejercicio personalizado | D36: =D20*D27*D11 -> 29.9 | E36: =E20*E27*E11 -> 44.85 | F36: =F20*F27*F11 -> 59.8 | G36: =G20*G27*G11 -> 74.75 | H36: =H20*H27*H11 -> 89.7 | I36: =I20*I27*I11 -> 104.65 | J36: =J20*J27*J11 -> 119.6 | K36: =K20*K27*K11 -> 149.5 | ... AM36: =AM20*AM27*AM11 -> 4245.8 | AN36: =SUM(D36:O36) -> 1719.25 | AO36: =SUM(P36:AA36) -> 11362 | AP36: =SUM(AB36:AM36) -> 37763.7
B37: Enterprise (€499/mes) | D37: =D21*D27*D12 -> 79.84 | E37: =E21*E27*E12 -> 119.76 | F37: =F21*F27*F12 -> 159.68 | G37: =G21*G27*G12 -> 199.6 | H37: =H21*H27*H12 -> 239.52 | I37: =I21*I27*I12 -> 279.44 | J37: =J21*J27*J12 -> 319.36 | K37: =K21*K27*K12 -> 399.2 | ... AM37: =AM21*AM27*AM12 -> 11337.28 | AN37: =SUM(D37:O37) -> 4590.8 | AO37: =SUM(P37:AA37) -> 30339.2 | AP37: =SUM(AB37:AM37) -> 100837.92
B38: B2C (€5/reto extra, 3% candidatos) | D38: =D32*D17*D13 -> 0 | E38: =E32*E17*E13 -> 0 | F38: =F32*F17*F13 -> 0 | G38: =G32*G17*G13 -> 0 | H38: =H32*H17*H13 -> 0 | I38: =I32*I17*I13 -> 0 | J38: =J32*J17*J13 -> 0 | K38: =K32*K17*K13 -> 54.15 | ... AM38: =AM32*AM17*AM13 -> 1311.9 | AN38: =SUM(D38:O38) -> 412.2 | AO38: =SUM(P38:AA38) -> 3751.95 | AP38: =SUM(AB38:AM38) -> 11217.45
B39: INGRESO BRUTO TOTAL | D39: =D34+D35+D36+D37+D38 -> 282.152 | E39: =E34+E35+E36+E37+E38 -> 423.228 | F39: =F34+F35+F36+F37+F38 -> 564.304 | G39: =G34+G35+G36+G37+G38 -> 705.38 | H39: =H34+H35+H36+H37+H38 -> 846.456 | I39: =I34+I35+I36+I37+I38 -> 987.532 | J39: =J34+J35+J36+J37+J38 -> 1128.608 | K39: =K34+K35+K36+K37+K38 -> 1464.91 | ... AM39: =AM34+AM35+AM36+AM37+AM38 -> 41377.484 | AN39: =SUM(D39:O39) -> 16635.94 | AO39: =SUM(P39:AA39) -> 110969.71 | AP39: =SUM(AB39:AM39) -> 367575.43
B40: (-) Comisión Stripe (2%) | D40: =-D14*D39 -> -5.64304 | E40: =-E14*E39 -> -8.46456 | F40: =-F14*F39 -> -11.28608 | G40: =-G14*G39 -> -14.1076 | H40: =-H14*H39 -> -16.92912 | I40: =-I14*I39 -> -19.75064 | J40: =-J14*J39 -> -22.57216 | K40: =-K14*K39 -> -29.2982 | ... AM40: =-AM14*AM39 -> -827.54968 | AN40: =SUM(D40:O40) -> -332.7188 | AO40: =SUM(P40:AA40) -> -2219.3942 | AP40: =SUM(AB40:AM40) -> -7351.5085
...

Sheet COGS & SG&A
B1: TalentPact — COGS, SG&A & Estructura de Costes (36 meses)
B2: Año | C2: Ref. | D2: 2026 | E2: 2026 | F2: 2026 | G2: 2026 | H2: 2026 | I2: 2026 | J2: 2026 | K2: 2026 | L2: 2026 | M2: 2026 | N2: 2026 | O2: 2026 | P2: 2027 | Q2: 2027 | R2: 2027 | S2: 2027 | T2: 2027 | U2: 2027 | V2: 2027 | W2: 2027 | X2: 2027 | Y2: 2027 | Z2: 2027 | AA2: 2027 | AB2: 2028 | AC2: 2028 | AD2: 2028 | AE2: 2028 | AF2: 2028 | AG2: 2028 | AH2: 2028 | AI2: 2028 | AJ2: 2028 | AK2: 2028 | AL2: 2028 | AM2: 2028 | AN2: Total 2026 | AO2: Total 2027 | AP2: Total 2028
B3: COGS & SG&A Buildup | C3: Ref. | D3: Jan 2026 | E3: Feb 2026 | F3: Mar 2026 | G3: Apr 2026 | H3: May 2026 | I3: Jun 2026 | J3: Jul 2026 | K3: Aug 2026 | L3: Sep 2026 | M3: Oct 2026 | N3: Nov 2026 | O3: Dec 2026 | P3: Jan 2027 | Q3: Feb 2027 | R3: Mar 2027 | S3: Apr 2027 | T3: May 2027 | U3: Jun 2027 | V3: Jul 2027 | W3: Aug 2027 | X3: Sep 2027 | Y3: Oct 2027 | Z3: Nov 2027 | AA3: Dec 2027 | AB3: Jan 2028 | AC3: Feb 2028 | AD3: Mar 2028 | AE3: Apr 2028 | AF3: May 2028 | AG3: Jun 2028 | AH3: Jul 2028 | AI3: Aug 2028 | AJ3: Sep 2028 | AK3: Oct 2028 | AL3: Nov 2028 | AM3: Dec 2028 | AN3: Total 2026 | AO3: Total 2027 | AP3: Total 2028
B4: SUPUESTOS COGS
B5: Coste API IA por ejercicio (€) | D5: 0.02 | E5: 0.02 | F5: 0.02 | G5: 0.02 | H5: 0.02 | I5: 0.02 | J5: 0.02 | K5: 0.02 | L5: 0.02 | M5: 0.02 | N5: 0.02 | O5: 0.02 | P5: 0.02 | Q5: 0.02 | R5: 0.02 | S5: 0.02 | T5: 0.02 | U5: 0.02 | V5: 0.02 | W5: 0.02 | X5: 0.02 | Y5: 0.02 | Z5: 0.02 | AA5: 0.02 | AB5: 0.02 | AC5: 0.02 | AD5: 0.02 | AE5: 0.02 | AF5: 0.02 | AG5: 0.02 | AH5: 0.02 | AI5: 0.02 | AJ5: 0.02 | AK5: 0.02 | AL5: 0.02 | AM5: 0.02
B6: Coste API IA por reto (€) | C6: €/reto | D6: =D5*3 -> 0.06 | E6: =E5*3 -> 0.06 | F6: =F5*3 -> 0.06 | G6: =G5*3 -> 0.06 | H6: =H5*3 -> 0.06 | I6: =I5*3 -> 0.06 | J6: =J5*3 -> 0.06 | K6: =K5*3 -> 0.06 | ... AM6: =AM5*3 -> 0.06
B7: Stripe comisión (%) | C7: % revenue | D7: 0.02 | E7: 0.02 | F7: 0.02 | G7: 0.02 | H7: 0.02 | I7: 0.02 | J7: 0.02 | K7: 0.02 | L7: 0.02 | M7: 0.02 | N7: 0.02 | O7: 0.02 | P7: 0.02 | Q7: 0.02 | R7: 0.02 | S7: 0.02 | T7: 0.02 | U7: 0.02 | V7: 0.02 | W7: 0.02 | X7: 0.02 | Y7: 0.02 | Z7: 0.02 | AA7: 0.02 | AB7: 0.02 | AC7: 0.02 | AD7: 0.02 | AE7: 0.02 | AF7: 0.02 | AG7: 0.02 | AH7: 0.02 | AI7: 0.02 | AJ7: 0.02 | AK7: 0.02 | AL7: 0.02 | AM7: 0.02
B8: SUPUESTOS SG&A
B9: Salarios fundadores (bruto mensual €)
B10: Fundador 1 (CEO) | D10: 1200 | E10: 1200 | F10: 1200 | G10: 1200 | H10: 1200 | I10: 1200 | J10: 1200 | K10: 1200 | L10: 1200 | M10: 1200 | N10: 1200 | O10: 1200 | P10: 2000 | Q10: 2000 | R10: 2000 | S10: 2000 | T10: 2000 | U10: 2000 | V10: 2000 | W10: 2000 | X10: 2000 | Y10: 2000 | Z10: 2000 | AA10: 2000 | AB10: 3000 | AC10: 3000 | AD10: 3000 | AE10: 3000 | AF10: 3000 | AG10: 3000 | AH10: 3000 | AI10: 3000 | AJ10: 3000 | AK10: 3000 | AL10: 3000 | AM10: 3000
B11: Fundador 2 (CTO) | D11: 1200 | E11: 1200 | F11: 1200 | G11: 1200 | H11: 1200 | I11: 1200 | J11: 1200 | K11: 1200 | L11: 1200 | M11: 1200 | N11: 1200 | O11: 1200 | P11: 2000 | Q11: 2000 | R11: 2000 | S11: 2000 | T11: 2000 | U11: 2000 | V11: 2000 | W11: 2000 | X11: 2000 | Y11: 2000 | Z11: 2000 | AA11: 2000 | AB11: 3000 | AC11: 3000 | AD11: 3000 | AE11: 3000 | AF11: 3000 | AG11: 3000 | AH11: 3000 | AI11: 3000 | AJ11: 3000 | AK11: 3000 | AL11: 3000 | AM11: 3000
B12: Fundador 3 (Product) | D12: 1200 | E12: 1200 | F12: 1200 | G12: 1200 | H12: 1200 | I12: 1200 | J12: 1200 | K12: 1200 | L12: 1200 | M12: 1200 | N12: 1200 | O12: 1200 | P12: 2000 | Q12: 2000 | R12: 2000 | S12: 2000 | T12: 2000 | U12: 2000 | V12: 2000 | W12: 2000 | X12: 2000 | Y12: 2000 | Z12: 2000 | AA12: 2000 | AB12: 3000 | AC12: 3000 | AD12: 3000 | AE12: 3000 | AF12: 3000 | AG12: 3000 | AH12: 3000 | AI12: 3000 | AJ12: 3000 | AK12: 3000 | AL12: 3000 | AM12: 3000
B13: Fundador 4 (Growth) | D13: 1200 | E13: 1200 | F13: 1200 | G13: 1200 | H13: 1200 | I13: 1200 | J13: 1200 | K13: 1200 | L13: 1200 | M13: 1200 | N13: 1200 | O13: 1200 | P13: 2000 | Q13: 2000 | R13: 2000 | S13: 2000 | T13: 2000 | U13: 2000 | V13: 2000 | W13: 2000 | X13: 2000 | Y13: 2000 | Z13: 2000 | AA13: 2000 | AB13: 3000 | AC13: 3000 | AD13: 3000 | AE13: 3000 | AF13: 3000 | AG13: 3000 | AH13: 3000 | AI13: 3000 | AJ13: 3000 | AK13: 3000 | AL13: 3000 | AM13: 3000
B14: Desarrollador | P14: 2500 | Q14: 2500 | R14: 2500 | S14: 2500 | T14: 2500 | U14: 2500 | V14: 2500 | W14: 2500 | X14: 2500 | Y14: 2500 | Z14: 2500 | AA14: 2500 | AB14: 3000 | AC14: 3000 | AD14: 3000 | AE14: 3000 | AF14: 3000 | AG14: 3000 | AH14: 3000 | AI14: 3000 | AJ14: 3000 | AK14: 3000 | AL14: 3000 | AM14: 3000
B15: Marketing | P15: 1700 | Q15: 1700 | R15: 1700 | S15: 1700 | T15: 1700 | U15: 1700 | V15: 1700 | W15: 1700 | X15: 1700 | Y15: 1700 | Z15: 1700 | AA15: 1700 | AB15: 2500 | AC15: 2500 | AD15: 2500 | AE15: 2500 | AF15: 2500 | AG15: 2500 | AH15: 2500 | AI15: 2500 | AJ15: 2500 | AK15: 2500 | AL15: 2500 | AM15: 2500
B17: Seguros | F17: 400 | R17: 400 | AD17: 400
B19: SaaS de Equipo (Licencias) | D19: 55 | E19: 55 | F19: 55 | G19: 55 | H19: 55 | I19: 120 | J19: 120 | K19: 120 | L19: 120 | M19: 120 | N19: 120 | O19: 120 | P19: 120 | Q19: 120 | R19: 120 | S19: 120 | T19: 120 | U19: 250 | V19: 250 | W19: 250 | X19: 250 | Y19: 320 | Z19: 320 | AA19: 320 | AB19: 450 | AC19: 450 | AD19: 450 | AE19: 450 | AF19: 450 | AG19: 450 | AH19: 450 | AI19: 450 | AJ19: 450 | AK19: 450 | AL19: 450 | AM19: 450
B20: Infraestructura Fija | D20: 60 | E20: 60 | F20: 60 | G20: 60 | H20: 60 | I20: 60 | J20: 60 | K20: 60 | L20: 60 | M20: 60 | N20: 60 | O20: 60 | P20: 60 | Q20: 60 | R20: 60 | S20: 60 | T20: 60 | U20: 60 | V20: 60 | W20: 60 | X20: 60 | Y20: 60 | Z20: 60 | AA20: 60 | AB20: 60 | AC20: 60 | AD20: 60 | AE20: 60 | AF20: 60 | AG20: 60 | AH20: 60 | AI20: 60 | AJ20: 60 | AK20: 60 | AL20: 60 | AM20: 60
B21: Compliance y Seguridad | D21: 0 | E21: 0 | F21: 0 | G21: 0 | H21: 0 | I21: 0 | J21: 0 | K21: 0 | L21: 100 | M21: 100 | N21: 100 | O21: 100 | P21: 100 | Q21: 100 | R21: 100 | S21: 100 | T21: 100 | U21: 100 | V21: 100 | W21: 100 | X21: 100 | Y21: 100 | Z21: 100 | AA21: 100 | AB21: 100 | AC21: 100 | AD21: 100 | AE21: 100 | AF21: 100 | AG21: 100 | AH21: 100 | AI21: 100 | AJ21: 100 | AK21: 100 | AL21: 100 | AM21: 100
B22: Soporte Operaciones IA | D22: 0 | E22: 0 | F22: 0 | G22: 0 | H22: 0 | I22: 0 | J22: 0 | K22: 0 | L22: 50 | M22: 50 | N22: 50 | O22: 50 | P22: 50 | Q22: 50 | R22: 50 | S22: 50 | T22: 50 | U22: 50 | V22: 50 | W22: 50 | X22: 50 | Y22: 50 | Z22: 50 | AA22: 50 | AB22: 50 | AC22: 50 | AD22: 50 | AE22: 50 | AF22: 50 | AG22: 50 | AH22: 50 | AI22: 50 | AJ22: 50 | AK22: 50 | AL22: 50 | AM22: 50
B23: LinkedIn Sales Navigator (€/mes) | D23: 79 | E23: 79 | F23: 79 | G23: 79 | H23: 79 | I23: 79 | J23: 79 | K23: 79 | L23: 79 | M23: 79 | N23: 79 | O23: 79 | P23: 79 | Q23: 79 | R23: 79 | S23: 79 | T23: 79 | U23: 79 | V23: 79 | W23: 79 | X23: 79 | Y23: 79 | Z23: 79 | AA23: 79 | AB23: 79 | AC23: 79 | AD23: 79 | AE23: 79 | AF23: 79 | AG23: 79 | AH23: 79 | AI23: 79 | AJ23: 79 | AK23: 79 | AL23: 79 | AM23: 79
B24: Hosting Supabase+Vercel (€/mes) | D24: 39.5 | E24: 39.5 | F24: 39.5 | G24: 39.5 | H24: 39.5 | I24: 39.5 | J24: 39.5 | K24: 39.5 | L24: 39.5 | M24: 39.5 | N24: 39.5 | O24: 39.5 | P24: 85 | Q24: 85 | R24: 85 | S24: 85 | T24: 85 | U24: 85 | V24: 85 | W24: 85 | X24: 85 | Y24: 85 | Z24: 85 | AA24: 85 | AB24: 158 | AC24: 158 | AD24: 158 | AE24: 158 | AF24: 158 | AG24: 158 | AH24: 158 | AI24: 158 | AJ24: 158 | AK24: 158 | AL24: 158 | AM24: 158
B25: Plataformas digitales Notion/Slack (€/mes) | D25: 200 | E25: 200 | F25: 200 | G25: 200 | H25: 200 | I25: 200 | J25: 200 | K25: 200 | L25: 200 | M25: 200 | N25: 200 | O25: 200 | P25: 350 | Q25: 350 | R25: 350 | S25: 350 | T25: 350 | U25: 350 | V25: 350 | W25: 350 | X25: 350 | Y25: 350 | Z25: 350 | AA25: 350 | AB25: 500 | AC25: 500 | AD25: 500 | AE25: 500 | AF25: 500 | AG25: 500 | AH25: 500 | AI25: 500 | AJ25: 500 | AK25: 500 | AL25: 500 | AM25: 500
B26: Legal | D26: 1000 | E26: 1250 | G26: 0 | H26: 0 | I26: 120 | J26: 120 | K26: 120 | L26: 120 | M26: 120 | N26: 120 | O26: 120 | P26: 120 | Q26: 120 | R26: 120 | S26: 120 | T26: 120 | U26: 120 | V26: 120 | W26: 120 | X26: 120 | Y26: 120 | Z26: 120 | AA26: 120 | AB26: 120 | AC26: 120 | AD26: 120 | AE26: 120 | AF26: 120 | AG26: 120 | AH26: 120 | AI26: 120 | AJ26: 120 | AK26: 120 | AL26: 120 | AM26: 120
B27: Contabilidad | D27: 1400 | E27: 200 | F27: 200 | G27: 600 | H27: 200 | I27: 200 | J27: 600 | K27: 200 | L27: 200 | M27: 200 | N27: 200 | O27: 200 | P27: 200 | Q27: 200 | R27: 200 | S27: 600 | T27: 200 | U27: 200 | V27: 600 | W27: 200 | X27: 200 | Y27: 200 | Z27: 200 | AA27: 200 | AB27: 200 | AC27: 200 | AD27: 200 | AE27: 600 | AF27: 200 | AG27: 200 | AH27: 600 | AI27: 200 | AJ27: 200 | AK27: 200 | AL27: 200 | AM27: 200
B28: CAC / Marketing Acquisition (€/mes) | D28: =300*0.79 -> 237 | E28: =300*0.79 -> 237 | F28: =450*0.79 -> 355.5 | G28: 300 | H28: 300 | I28: 300 | J28: 300 | K28: =555*0.79 -> 438.45 | L28: =0.79*740 -> 584.6 | M28: =0.79*925 -> 730.75 | N28: =0.79*1480 -> 1169.2 | O28: =0.79*1850 -> 1461.5 | P28: =0.79*1850 -> 1461.5 | Q28: =0.79*1850 -> 1461.5 | R28: =0.79*2000 -> 1580 | S28: =0.79*2000 -> 1580 | T28: =0.79*2200 -> 1738 | U28: =0.79*2200 -> 1738 | V28: =0.79*2500 -> 1975 | W28: =0.79*2800 -> 2212 | X28: =0.79*3000 -> 2370 | Y28: =0.79*3500 -> 2765 | Z28: =0.79*4000 -> 3160 | AA28: =0.79*4500 -> 3555 | AB28: =0.79*5000 -> 3950 | AC28: =0.79*5000 -> 3950 | AD28: =0.79*5500 -> 4345 | AE28: =0.79*5500 -> 4345 | AF28: =0.79*6000 -> 4740 | AG28: =0.79*6000 -> 4740 | AH28: =0.79*6500 -> 5135 | AI28: =0.79*7000 -> 5530 | AJ28: =0.79*7000 -> 5530 | AK28: =0.79*7500 -> 5925 | AL28: =0.79*8000 -> 6320 | AM28: =0.79*8500 -> 6715
B29: COGS BUILDUP
B30: API IA (Claude) — €/reto × retos de candidato | D30: =(('MODELO NORMAL'!D32 * 0.97 * 3) + ('MODELO NORMAL'!D32 * 0.03 * 15)) * 'COGS & SG&A'!D6 -> 6.048 | E30: =(('MODELO NORMAL'!E32 * 0.97 * 3) + ('MODELO NORMAL'!E32 * 0.03 * 15)) * 'COGS & SG&A'!E6 -> 10.08 | F30: =(('MODELO NORMAL'!F32 * 0.97 * 3) + ('MODELO NORMAL'!F32 * 0.03 * 15)) * 'COGS & SG&A'!F6 -> 13.104 | G30: =(('MODELO NORMAL'!G32 * 0.97 * 3) + ('MODELO NORMAL'!G32 * 0.03 * 15)) * 'COGS & SG&A'!G6 -> 19.7568 | H30: =(('MODELO NORMAL'!H32 * 0.97 * 3) + ('MODELO NORMAL'!H32 * 0.03 * 15)) * 'COGS & SG&A'!H6 -> 29.6352 | I30: =(('MODELO NORMAL'!I32 * 0.97 * 3) + ('MODELO NORMAL'!I32 * 0.03 * 15)) * 'COGS & SG&A'!I6 -> 41.5296 | J30: =(('MODELO NORMAL'!J32 * 0.97 * 3) + ('MODELO NORMAL'!J32 * 0.03 * 15)) * 'COGS & SG&A'!J6 -> 56.0448 | K30: =(('MODELO NORMAL'!K32 * 0.97 * 3) + ('MODELO NORMAL'!K32 * 0.03 * 15)) * 'COGS & SG&A'!K6 -> 72.7776 | ... AM30: =(('MODELO NORMAL'!AM32 * 0.97 * 3) + ('MODELO NORMAL'!AM32 * 0.03 * 15)) * 'COGS & SG&A'!AM6 -> 1763.1936 | AN30: =SUM(D30:O30) -> 730.1952 | AO30: =SUM(P30:AA30) -> 5042.6208 | AP30: =SUM(AB30:AM30) -> 15076.253
B31: Stripe comisión (2% revenue bruto) | D31: =D7*'MODELO NORMAL'!D39 -> 5.64304 | E31: =E7*'MODELO NORMAL'!E39 -> 8.46456 | F31: =F7*'MODELO NORMAL'!F39 -> 11.28608 | G31: =G7*'MODELO NORMAL'!G39 -> 14.1076 | H31: =H7*'MODELO NORMAL'!H39 -> 16.92912 | I31: =I7*'MODELO NORMAL'!I39 -> 19.75064 | J31: =J7*'MODELO NORMAL'!J39 -> 22.57216 | K31: =K7*'MODELO NORMAL'!K39 -> 29.2982 | ... AM31: =AM7*'MODELO NORMAL'!AM39 -> 827.54968 | AN31: =SUM(D31:O31) -> 332.7188 | AO31: =SUM(P31:AA31) -> 2219.3942 | AP31: =SUM(AB31:AM31) -> 7351.5085
B32: TOTAL COGS | D32: =D30+D31 -> 11.69104 | E32: =E30+E31 -> 18.54456 | F32: =F30+F31 -> 24.39008 | G32: =G30+G31 -> 33.8644 | H32: =H30+H31 -> 46.56432 | I32: =I30+I31 -> 61.28024 | J32: =J30+J31 -> 78.61696 | K32: =K30+K31 -> 102.0758 | ... AP32: =AP30+AP31 -> 22427.761
B33: SG&A BUILDUP
B34: Total Salarios (4 fundadores) | D34: =D10+D11+D12+D13+D14+D15 -> 4800 | E34: =E10+E11+E12+E13+E14+E15 -> 4800 | F34: =F10+F11+F12+F13+F14+F15 -> 4800 | G34: =G10+G11+G12+G13+G14+G15 -> 4800 | H34: =H10+H11+H12+H13+H14+H15 -> 4800 | I34: =I10+I11+I12+I13+I14+I15 -> 4800 | J34: =J10+J11+J12+J13+J14+J15 -> 4800 | K34: =K10+K11+K12+K13+K14+K15 -> 4800 | ... AM34: =AM10+AM11+AM12+AM13+AM14+AM15 -> 17500 | AN34: =SUM(D34:O34) -> 57600 | AO34: =SUM(P34:AA34) -> 146400 | AP34: =SUM(AB34:AM34) -> 210000
B35: Seguros | D35: =D17 -> 0 | E35: =E17 -> 0 | F35: =F17 -> 400 | G35: =G17 -> 0 | H35: =H17 -> 0 | I35: =I17 -> 0 | J35: =J17 -> 0 | K35: =K17 -> 0 | ... AM35: =AM17 -> 0 | AN35: =SUM(D35:O35) -> 400 | AO35: =SUM(P35:AA35) -> 400 | AP35: =SUM(AB35:AM35) -> 400
B36: SaaS de Equipo (Licencias) | D36: =D19 -> 55 | E36: =E19 -> 55 | F36: =F19 -> 55 | G36: =G19 -> 55 | H36: =H19 -> 55 | I36: =I19 -> 120 | J36: =J19 -> 120 | K36: =K19 -> 120 | ... AM36: =AM19 -> 450 | AN36: =SUM(D36:O36) -> 1115 | AO36: =SUM(P36:AA36) -> 2560 | AP36: =SUM(Q36:AB36) -> 2890
B37: Infraestructura Fija | D37: =D20 -> 60 | E37: =E20 -> 60 | F37: =F20 -> 60 | G37: =G20 -> 60 | H37: =H20 -> 60 | I37: =I20 -> 60 | J37: =J20 -> 60 | K37: =K20 -> 60 | ... AM37: =AM20 -> 60 | AN37: =SUM(D37:O37) -> 720 | AO37: =SUM(P37:AA37) -> 720 | AP37: =SUM(AB37:AM37) -> 720
B38: Compliance y Seguridad | D38: =D21 -> 0 | E38: =E21 -> 0 | F38: =F21 -> 0 | G38: =G21 -> 0 | H38: =H21 -> 0 | I38: =I21 -> 0 | J38: =J21 -> 0 | K38: =K21 -> 0 | ... AM38: =AM21 -> 100 | AN38: =SUM(D38:O38) -> 400 | AO38: =SUM(P38:AA38) -> 1200 | AP38: =SUM(AB38:AM38) -> 1200
B39: Soporte Operaciones IA | D39: =D22 -> 0 | E39: =E22 -> 0 | F39: =F22 -> 0 | G39: =G22 -> 0 | H39: =H22 -> 0 | I39: =I22 -> 0 | J39: =J22 -> 0 | K39: =K22 -> 0 | ... AM39: =AM22 -> 50 | AN39: =SUM(D39:O39) -> 200 | AO39: =SUM(P39:AA39) -> 600 | AP39: =SUM(AB39:AM39) -> 600
B40: LinkedIn Sales Navigator | D40: =D23 -> 79 | E40: =E23 -> 79 | F40: =F23 -> 79 | G40: =G23 -> 79 | H40: =H23 -> 79 | I40: =I23 -> 79 | J40: =J23 -> 79 | K40: =K23 -> 79 | ... AM40: =AM23 -> 79 | AN40: =SUM(D40:O40) -> 948 | AO40: =SUM(P40:AA40) -> 948 | AP40: =SUM(AB40:AM40) -> 948
B41: Hosting (Supabase + Vercel) | D41: =D24 -> 39.5 | E41: =E24 -> 39.5 | F41: =F24 -> 39.5 | G41: =G24 -> 39.5 | H41: =H24 -> 39.5 | I41: =I24 -> 39.5 | J41: =J24 -> 39.5 | K41: =K24 -> 39.5 | ... AM41: =AM24 -> 158 | AN41: =SUM(D41:O41) -> 474 | AO41: =SUM(P41:AA41) -> 1020 | AP41: =SUM(AB41:AM41) -> 1896
B42: Plataformas digitales | D42: =D25 -> 200 | E42: =E25 -> 200 | F42: =F25 -> 200 | G42: =G25 -> 200 | H42: =H25 -> 200 | I42: =I25 -> 200 | J42: =J25 -> 200 | K42: =K25 -> 200 | ... AM42: =AM25 -> 500 | AN42: =SUM(D42:O42) -> 2400 | AO42: =SUM(P42:AA42) -> 4200 | AP42: =SUM(AB42:AM42) -> 6000
...

Sheet P&L
B1: TalentPact — Cuenta de Resultados P&L (36 meses)
B2: Año | C2: Nota | D2: 2026 | E2: 2026 | F2: 2026 | G2: 2026 | H2: 2026 | I2: 2026 | J2: 2026 | K2: 2026 | L2: 2026 | M2: 2026 | N2: 2026 | O2: 2026 | P2: 2027 | Q2: 2027 | R2: 2027 | S2: 2027 | T2: 2027 | U2: 2027 | V2: 2027 | W2: 2027 | X2: 2027 | Y2: 2027 | Z2: 2027 | AA2: 2027 | AB2: 2028 | AC2: 2028 | AD2: 2028 | AE2: 2028 | AF2: 2028 | AG2: 2028 | AH2: 2028 | AI2: 2028 | AJ2: 2028 | AK2: 2028 | AL2: 2028 | AM2: 2028 | AN2: Total 2026 | AO2: Total 2027 | AP2: Total 2028
B3: P&L (€) | C3: Nota | D3: Jan 2026 | E3: Feb 2026 | F3: Mar 2026 | G3: Apr 2026 | H3: May 2026 | I3: Jun 2026 | J3: Jul 2026 | K3: Aug 2026 | L3: Sep 2026 | M3: Oct 2026 | N3: Nov 2026 | O3: Dec 2026 | P3: Jan 2027 | Q3: Feb 2027 | R3: Mar 2027 | S3: Apr 2027 | T3: May 2027 | U3: Jun 2027 | V3: Jul 2027 | W3: Aug 2027 | X3: Sep 2027 | Y3: Oct 2027 | Z3: Nov 2027 | AA3: Dec 2027 | AB3: Jan 2028 | AC3: Feb 2028 | AD3: Mar 2028 | AE3: Apr 2028 | AF3: May 2028 | AG3: Jun 2028 | AH3: Jul 2028 | AI3: Aug 2028 | AJ3: Sep 2028 | AK3: Oct 2028 | AL3: Nov 2028 | AM3: Dec 2028 | AN3: Total 2026 | AO3: Total 2027 | AP3: Total 2028
B4: INGRESO BRUTO | D4: ='MODELO NORMAL'!D39 -> 282.152 | E4: ='MODELO NORMAL'!E39 -> 423.228 | F4: ='MODELO NORMAL'!F39 -> 564.304 | G4: ='MODELO NORMAL'!G39 -> 705.38 | H4: ='MODELO NORMAL'!H39 -> 846.456 | I4: ='MODELO NORMAL'!I39 -> 987.532 | J4: ='MODELO NORMAL'!J39 -> 1128.608 | K4: ='MODELO NORMAL'!K39 -> 1464.91 | ... AM4: ='MODELO NORMAL'!AM39 -> 41377.484 | AN4: =SUM(D4:O4) -> 16635.94 | AO4: =SUM(P4:AA4) -> 110969.71 | AP4: =SUM(AB4:AM4) -> 367575.43
B5: (-) Stripe 2% | D5: ='MODELO NORMAL'!D40 -> -5.64304 | E5: ='MODELO NORMAL'!E40 -> -8.46456 | F5: ='MODELO NORMAL'!F40 -> -11.28608 | G5: ='MODELO NORMAL'!G40 -> -14.1076 | H5: ='MODELO NORMAL'!H40 -> -16.92912 | I5: ='MODELO NORMAL'!I40 -> -19.75064 | J5: ='MODELO NORMAL'!J40 -> -22.57216 | K5: ='MODELO NORMAL'!K40 -> -29.2982 | ... AM5: ='MODELO NORMAL'!AM40 -> -827.54968 | AN5: =SUM(D5:O5) -> -332.7188 | AO5: =SUM(P5:AA5) -> -2219.3942 | AP5: =SUM(AB5:AM5) -> -7351.5085
B6: INGRESO NETO (Net Revenue) | D6: ='MODELO NORMAL'!D41 -> 276.50896 | E6: ='MODELO NORMAL'!E41 -> 414.76344 | F6: ='MODELO NORMAL'!F41 -> 553.01792 | G6: ='MODELO NORMAL'!G41 -> 691.2724 | H6: ='MODELO NORMAL'!H41 -> 829.52688 | I6: ='MODELO NORMAL'!I41 -> 967.78136 | J6: ='MODELO NORMAL'!J41 -> 1106.0358 | K6: ='MODELO NORMAL'!K41 -> 1435.6118 | ... AM6: ='MODELO NORMAL'!AM41 -> 40549.934 | AN6: =SUM(D6:O6) -> 16303.221 | AO6: =SUM(P6:AA6) -> 108750.32 | AP6: =SUM(AB6:AM6) -> 360223.92
B7: MoM crecimiento % | D7: N/A | E7: =IF(D6>0,(E6-D6)/D6,"N/A") -> 0.5 | F7: =IF(E6>0,(F6-E6)/E6,"N/A") -> 0.33333333 | G7: =IF(F6>0,(G6-F6)/F6,"N/A") -> 0.25 | H7: =IF(G6>0,(H6-G6)/G6,"N/A") -> 0.2 | I7: =IF(H6>0,(I6-H6)/H6,"N/A") -> 0.16666667 | J7: =IF(I6>0,(J6-I6)/I6,"N/A") -> 0.14285714 | K7: =IF(J6>0,(K6-J6)/J6,"N/A") -> 0.29797946 | L7: =IF(K6>0,(L6-K6)/K6,"N/A") -> 0.20182264 | ... AM7: =IF(AL6>0,(AM6-AL6)/AL6,"N/A") -> 0.048347465
B8: (-) COGS Total | D8: =-'COGS & SG&A'!D32 -> -11.69104 | E8: =-'COGS & SG&A'!E32 -> -18.54456 | F8: =-'COGS & SG&A'!F32 -> -24.39008 | G8: =-'COGS & SG&A'!G32 -> -33.8644 | H8: =-'COGS & SG&A'!H32 -> -46.56432 | I8: =-'COGS & SG&A'!I32 -> -61.28024 | J8: =-'COGS & SG&A'!J32 -> -78.61696 | K8: =-'COGS & SG&A'!K32 -> -102.0758 | ... AM8: =-'COGS & SG&A'!AM32 -> -2590.7433 | AN8: =SUM(D8:O8) -> -1062.914 | AO8: =SUM(P8:AA8) -> -7262.015 | AP8: =SUM(AB8:AM8) -> -22427.761
B9: GROSS PROFIT | D9: =D6+D8 -> 264.81792 | E9: =E6+E8 -> 396.21888 | F9: =F6+F8 -> 528.62784 | G9: =G6+G8 -> 657.408 | H9: =H6+H8 -> 782.96256 | I9: =I6+I8 -> 906.50112 | J9: =J6+J8 -> 1027.4189 | K9: =K6+K8 -> 1333.536 | ... AM9: =AM6+AM8 -> 37959.191 | AN9: =SUM(D9:O9) -> 15240.307 | AO9: =SUM(P9:AA9) -> 101488.3 | AP9: =SUM(AB9:AM9) -> 337796.16
B10: Gross Margin % | D10: =IF(D6>0,D9/D6,0) -> 0.95771913 | E10: =IF(E6>0,E9/E6,0) -> 0.95528883 | F10: =IF(F6>0,F9/F6,0) -> 0.9558964 | G10: =IF(G6>0,G9/G6,0) -> 0.9510115 | H10: =IF(H6>0,H9/H6,0) -> 0.94386641 | I10: =IF(I6>0,I9/I6,0) -> 0.93667966 | J10: =IF(J6>0,J9/J6,0) -> 0.92892006 | K10: =IF(K6>0,K9/K6,0) -> 0.92889735 | ... AM10: =IF(AM6>0,AM9/AM6,0) -> 0.9361098
B11: (-) Marketing & CAC | D11: =-'COGS & SG&A'!D46 -> -670.5 | E11: =-'COGS & SG&A'!E46 -> -670.5 | F11: =-'COGS & SG&A'!F46 -> -789 | G11: =-'COGS & SG&A'!G46 -> -733.5 | H11: =-'COGS & SG&A'!H46 -> -733.5 | I11: =-'COGS & SG&A'!I46 -> -798.5 | J11: =-'COGS & SG&A'!J46 -> -798.5 | K11: =-'COGS & SG&A'!K46 -> -936.95 | ... AM11: =-'COGS & SG&A'!AM46 -> -8012 | AN11: =SUM(D11:O11) -> -12271 | AO11: =SUM(P11:AA11) -> -35644 | AP11: =SUM(AB11:AM11) -> -76789
B12: (-) Administración | D12: =-'COGS & SG&A'!D47 -> -2400 | E12: =-'COGS & SG&A'!E47 -> -1450 | F12: =-'COGS & SG&A'!F47 -> -200 | G12: =-'COGS & SG&A'!G47 -> -600 | H12: =-'COGS & SG&A'!H47 -> -200 | I12: =-'COGS & SG&A'!I47 -> -320 | J12: =-'COGS & SG&A'!J47 -> -720 | K12: =-'COGS & SG&A'!K47 -> -320 | ... AM12: =-'COGS & SG&A'!AM47 -> -420 | AN12: =SUM(D12:O12) -> -7890 | AO12: =SUM(P12:AA12) -> -5840 | AP12: =SUM(AB12:AM12) -> -5840
B13: (-) Seguros | D13: =-'COGS & SG&A'!D35 -> 0 | E13: =-'COGS & SG&A'!E35 -> 0 | F13: =-'COGS & SG&A'!F35 -> -400 | G13: =-'COGS & SG&A'!G35 -> 0 | H13: =-'COGS & SG&A'!H35 -> 0 | I13: =-'COGS & SG&A'!I35 -> 0 | J13: =-'COGS & SG&A'!J35 -> 0 | K13: =-'COGS & SG&A'!K35 -> 0 | ... AM13: =-'COGS & SG&A'!AM35 -> 0
B14: (-) Salarios | D14: =-'COGS & SG&A'!D34 -> -4800 | E14: =-'COGS & SG&A'!E34 -> -4800 | F14: =-'COGS & SG&A'!F34 -> -4800 | G14: =-'COGS & SG&A'!G34 -> -4800 | H14: =-'COGS & SG&A'!H34 -> -4800 | I14: =-'COGS & SG&A'!I34 -> -4800 | J14: =-'COGS & SG&A'!J34 -> -4800 | K14: =-'COGS & SG&A'!K34 -> -4800 | ... AM14: =-'COGS & SG&A'!AM34 -> -17500 | AN14: =SUM(D14:O14) -> -57600 | AO14: =SUM(P14:AA14) -> -146400 | AP14: =SUM(AB14:AM14) -> -210000
B15: (-) TOTAL SG&A | D15: =D11+D12+D14 -> -7870.5 | E15: =E11+E12+E14 -> -6920.5 | F15: =F11+F12+F14 -> -5789 | G15: =G11+G12+G14 -> -6133.5 | H15: =H11+H12+H14 -> -5733.5 | I15: =I11+I12+I14 -> -5918.5 | J15: =J11+J12+J14 -> -6318.5 | K15: =K11+K12+K14 -> -6056.95 | ... AM15: =AM11+AM12+AM14 -> -25932 | AN15: =SUM(D15:O15) -> -77761 | AO15: =SUM(P15:AA15) -> -187884 | AP15: =SUM(AB15:AM15) -> -292629
B16: (-) TOTAL SG&A ESCENARIO | D16: =D15*'MODELO NORMAL'!$C$4 -> -7870.5 | E16: =E15*'MODELO NORMAL'!$C$4 -> -6920.5 | F16: =F15*'MODELO NORMAL'!$C$4 -> -5789 | G16: =G15*'MODELO NORMAL'!$C$4 -> -6133.5 | H16: =H15*'MODELO NORMAL'!$C$4 -> -5733.5 | I16: =I15*'MODELO NORMAL'!$C$4 -> -5918.5 | J16: =J15*'MODELO NORMAL'!$C$4 -> -6318.5 | K16: =K15*'MODELO NORMAL'!$C$4 -> -6056.95 | ... AM16: =AM15*'MODELO NORMAL'!$C$4 -> -25932 | AN16: =SUM(D16:O16) -> -77761 | AO16: =SUM(P16:AA16) -> -187884 | AP16: =SUM(AB16:AM16) -> -292629
B17: EBITDA | D17: =D9+D16 -> -7605.6821 | E17: =E9+E16 -> -6524.2811 | F17: =F9+F16 -> -5260.3722 | G17: =G9+G16 -> -5476.092 | H17: =H9+H16 -> -4950.5374 | I17: =I9+I16 -> -5011.9989 | J17: =J9+J16 -> -5291.0811 | K17: =K9+K16 -> -4723.414 | ... AM17: =AM9+AM16 -> 12027.191 | AN17: =SUM(D17:O17) -> -62520.693 | AO17: =SUM(P17:AA17) -> -86395.699 | AP17: =SUM(AB17:AM17) -> 45167.156
B18: EBITDA Margin % | D18: =IF(D4>0,D17/D4,0) -> -26.955974 | E18: =IF(E4>0,E17/E4,0) -> -15.415523 | F18: =IF(F4>0,F17/F4,0) -> -9.3218764 | G18: =IF(G4>0,G17/G4,0) -> -7.7633219 | H18: =IF(H4>0,H17/H4,0) -> -5.8485467 | I18: =IF(I4>0,I17/I4,0) -> -5.0752774 | J18: =IF(J4>0,J17/J4,0) -> -4.6881478 | K18: =IF(K4>0,K17/K4,0) -> -3.2243715 | ... AM18: =IF(AM4>0,AM17/AM4,0) -> 0.29066995
B19: (-) Impuestos (15% si EBITDA>0) | D19: =IF(D17>0,-D17*0.15,0) -> 0 | E19: =IF(E17>0,-E17*0.15,0) -> 0 | F19: =IF(F17>0,-F17*0.15,0) -> 0 | G19: =IF(G17>0,-G17*0.15,0) -> 0 | H19: =IF(H17>0,-H17*0.15,0) -> 0 | I19: =IF(I17>0,-I17*0.15,0) -> 0 | J19: =IF(J17>0,-J17*0.15,0) -> 0 | K19: =IF(K17>0,-K17*0.15,0) -> 0 | ... AM19: =IF(AM17>0,-AM17*0.15,0) -> -1804.0787 | AN19: =SUM(D19:O19) -> 0 | AO19: =SUM(P19:AA19) -> -21.613296 | AP19: =SUM(AB19:AM19) -> -8171.4411
B20: (-) Intereses Préstamo (ENISA) | D20: 0 | E20: 0 | F20: 0 | G20: 0 | H20: 0 | I20: 250 | J20: 250 | K20: 250 | L20: 250 | M20: 250 | N20: 250 | O20: 250 | P20: 250 | Q20: 250 | R20: 250 | S20: 250 | T20: 250 | U20: 250 | V20: 250 | W20: 250 | X20: 250 | Y20: 250 | Z20: 250 | AA20: 250 | AB20: 250 | AC20: 250 | AD20: 250 | AE20: 250 | AF20: 250 | AG20: 243.64 | AH20: 237.26 | AI20: 230.84 | AJ20: 224 | AK20: 217 | AL20: 211 | AM20: 204 | AN20: =SUM(D20:O20) -> 1750 | AO20: =SUM(P20:AA20) -> 3000 | AP20: =SUM(AB20:AM20) -> 2817.74
B21: RESULTADO NETO (Net Income) | D21: =D17+D19-D20 -> -7605.6821 | E21: =E17+E19-E20 -> -6524.2811 | F21: =F17+F19-F20 -> -5260.3722 | G21: =G17+G19-G20 -> -5476.092 | H21: =H17+H19-H20 -> -4950.5374 | I21: =I17+I19-I20 -> -5261.9989 | J21: =J17+J19-J20 -> -5541.0811 | K21: =K17+K19-K20 -> -4973.414 | ... AM21: =AM17+AM19-AM20 -> 10019.112 | AN21: =SUM(D21:O21) -> -64270.693 | AO21: =SUM(P21:AA21) -> -89417.312 | AP21: =SUM(AB21:AM21) -> 34177.975
B22: Net Margin % | D22: =IF(D6=0,0,D21/D6) -> -27.506096 | E22: =IF(E6=0,0,E21/E6) -> -15.730126 | F22: =IF(F6=0,0,F21/F6) -> -9.5121188 | G22: =IF(G6=0,0,G21/G6) -> -7.921757 | H22: =IF(H6=0,0,H21/H6) -> -5.9679048 | I22: =IF(I6=0,0,I21/I6) -> -5.4371773 | J22: =IF(J6=0,0,J21/J6) -> -5.0098568 | K22: =IF(K6=0,0,K21/K6) -> -3.4643167 | ... AM22: =IF(AM6=0,0,AM21/AM6) -> 0.24708085

Sheet Cashflow
B1: TalentPact — Flujo de Caja (Cashflow) 36 meses
B2: Año | C2: Nota | D2: 2026 | E2: 2026 | F2: 2026 | G2: 2026 | H2: 2026 | I2: 2026 | J2: 2026 | K2: 2026 | L2: 2026 | M2: 2026 | N2: 2026 | O2: 2026 | P2: 2027 | Q2: 2027 | R2: 2027 | S2: 2027 | T2: 2027 | U2: 2027 | V2: 2027 | W2: 2027 | X2: 2027 | Y2: 2027 | Z2: 2027 | AA2: 2027 | AB2: 2028 | AC2: 2028 | AD2: 2028 | AE2: 2028 | AF2: 2028 | AG2: 2028 | AH2: 2028 | AI2: 2028 | AJ2: 2028 | AK2: 2028 | AL2: 2028 | AM2: 2028 | AN2: Total 2026 | AO2: Total 2027 | AP2: Total 2028
B3: Cashflow (€) | C3: Nota | D3: Jan 2026 | E3: Feb 2026 | F3: Mar 2026 | G3: Apr 2026 | H3: May 2026 | I3: Jun 2026 | J3: Jul 2026 | K3: Aug 2026 | L3: Sep 2026 | M3: Oct 2026 | N3: Nov 2026 | O3: Dec 2026 | P3: Jan 2027 | Q3: Feb 2027 | R3: Mar 2027 | S3: Apr 2027 | T3: May 2027 | U3: Jun 2027 | V3: Jul 2027 | W3: Aug 2027 | X3: Sep 2027 | Y3: Oct 2027 | Z3: Nov 2027 | AA3: Dec 2027 | AB3: Jan 2028 | AC3: Feb 2028 | AD3: Mar 2028 | AE3: Apr 2028 | AF3: May 2028 | AG3: Jun 2028 | AH3: Jul 2028 | AI3: Aug 2028 | AJ3: Sep 2028 | AK3: Oct 2028 | AL3: Nov 2028 | AM3: Dec 2028 | AN3: Total 2026 | AO3: Total 2027 | AP3: Total 2028
B4: SUPUESTOS
B5: DSO — Días de cobro (días) | C5: 2
B6: DPO — Días de pago (días) | C6: 30
B7: Inyección equity Pre-Seed (€) — Mes 1 | C7: 180000
B8: Préstamo ENISA no dilutivo (€) — Mes 6 (Jun 2026) | C8: 50000
B9: ACTIVIDADES OPERATIVAS
B10: Resultado neto (Net Income) | D10: ='P&L'!D21 -> -7605.6821 | E10: ='P&L'!E21 -> -6524.2811 | F10: ='P&L'!F21 -> -5260.3722 | G10: ='P&L'!G21 -> -5476.092 | H10: ='P&L'!H21 -> -4950.5374 | I10: ='P&L'!I21 -> -5261.9989 | J10: ='P&L'!J21 -> -5541.0811 | K10: ='P&L'!K21 -> -4973.414 | ... AM10: ='P&L'!AM21 -> 10019.112 | AN10: =SUM(D10:O10) -> -64270.693 | AO10: =SUM(P10:AA10) -> -89417.312 | AP10: =SUM(AB10:AM10) -> 34177.975
B11: Cobros de Clientes (informativo) | D11: =('P&L'!D9)*1.21 -> 320.42968 | E11: =('P&L'!E9)*1.21 -> 479.42484 | F11: =('P&L'!F9)*1.21 -> 639.63969 | G11: =('P&L'!G9)*1.21 -> 795.46368 | H11: =('P&L'!H9)*1.21 -> 947.3847 | I11: =('P&L'!I9)*1.21 -> 1096.8664 | J11: =('P&L'!J9)*1.21 -> 1243.1768 | K11: =('P&L'!K9)*1.21 -> 1613.5786 | ... AM11: =('P&L'!AM9)*1.21 -> 45930.621 | AN11: =SUM(D11:O11) -> 18440.772 | AO11: =SUM(P11:AA11) -> 122800.84 | AP11: =SUM(AB11:AM11) -> 408733.35
B12: Pago a proveedores (informativo) | E12: =('COGS & SG&A'!E46+'COGS & SG&A'!E47)*1.21 -> 2565.805 | F12: =('COGS & SG&A'!F46+'COGS & SG&A'!F47)*1.21 -> 1196.69 | G12: =('COGS & SG&A'!G46+'COGS & SG&A'!G47)*1.21 -> 1613.535 | H12: =('COGS & SG&A'!H46+'COGS & SG&A'!H47)*1.21 -> 1129.535 | I12: =('COGS & SG&A'!I46+'COGS & SG&A'!I47)*1.21 -> 1353.385 | J12: =('COGS & SG&A'!J46+'COGS & SG&A'!J47)*1.21 -> 1837.385 | K12: =('COGS & SG&A'!K46+'COGS & SG&A'!K47)*1.21 -> 1520.9095 | L12: =('COGS & SG&A'!L46+'COGS & SG&A'!L47)*1.21 -> 1879.251 | ... AM12: =('COGS & SG&A'!AM46+'COGS & SG&A'!AM47)*1.21 -> 10202.72 | AN12: =SUM(D12:O12) -> 20679.505 | AO12: =SUM(P12:AA12) -> 50195.64 | AP12: =SUM(AB12:AM12) -> 99981.09
B13: Pago seguros (informativo) | E13: ='COGS & SG&A'!D35 -> 0 | F13: ='COGS & SG&A'!E35 -> 0 | G13: ='COGS & SG&A'!F35 -> 400 | H13: ='COGS & SG&A'!G35 -> 0 | I13: ='COGS & SG&A'!H35 -> 0 | J13: ='COGS & SG&A'!I35 -> 0 | K13: ='COGS & SG&A'!J35 -> 0 | L13: ='COGS & SG&A'!K35 -> 0 | ... AM13: ='COGS & SG&A'!AL35 -> 0 | AN13: =SUM(D13:O13) -> 400 | AO13: =SUM(P13:AA13) -> 400 | AP13: =SUM(AB13:AM13) -> 400
B14: Pago personal (informativo) | D14: ='COGS & SG&A'!D34 -> 4800 | E14: ='COGS & SG&A'!E34 -> 4800 | F14: ='COGS & SG&A'!F34 -> 4800 | G14: ='COGS & SG&A'!G34 -> 4800 | H14: ='COGS & SG&A'!H34 -> 4800 | I14: ='COGS & SG&A'!I34 -> 4800 | J14: ='COGS & SG&A'!J34 -> 4800 | K14: ='COGS & SG&A'!K34 -> 4800 | ... AM14: ='COGS & SG&A'!AM34 -> 17500 | AN14: =SUM(D14:O14) -> 57600 | AO14: =SUM(P14:AA14) -> 146400 | AP14: =SUM(AB14:AM14) -> 210000
B15: Variación Cuentas por Pagar (informativo) | D15: =('COGS & SG&A'!D32/365*$C$6) -> 0.9609074 | E15: =(('COGS & SG&A'!E32-'COGS & SG&A'!D32)/365*$C$6) -> 0.56330301 | F15: =(('COGS & SG&A'!F32-'COGS & SG&A'!E32)/365*$C$6) -> 0.4804537 | G15: =(('COGS & SG&A'!G32-'COGS & SG&A'!F32)/365*$C$6) -> 0.77871123 | H15: =(('COGS & SG&A'!H32-'COGS & SG&A'!G32)/365*$C$6) -> 1.043829 | I15: =(('COGS & SG&A'!I32-'COGS & SG&A'!H32)/365*$C$6) -> 1.2095277 | J15: =(('COGS & SG&A'!J32-'COGS & SG&A'!I32)/365*$C$6) -> 1.4249359 | K15: =(('COGS & SG&A'!K32-'COGS & SG&A'!J32)/365*$C$6) -> 1.9281238 | L15: =(('COGS & SG&A'!L32-'COGS & SG&A'!K32)/365*$C$6) -> 1.977291 | ... AM15: =(('COGS & SG&A'!AM32-'COGS & SG&A'!AL32)/365*$C$6) -> 11.338912 | AN15: =SUM(D15:O15) -> 18.110801 | AO15: =SUM(P15:AA15) -> 72.461934 | AP15: =SUM(AB15:AM15) -> 122.36507
B16: Amortización Principal ENISA | D16: 0 | E16: 0 | F16: 0 | G16: 0 | H16: 0 | I16: 0 | J16: 0 | K16: 0 | L16: 0 | M16: 0 | N16: 0 | O16: 0 | P16: 0 | Q16: 0 | R16: 0 | S16: 0 | T16: 0 | U16: 0 | V16: 0 | W16: 0 | X16: 0 | Y16: 0 | Z16: 0 | AA16: 0 | AB16: 0 | AC16: 0 | AD16: 0 | AE16: 0 | AF16: 0 | AG16: -1271.1 | AH16: -1277.45 | AI16: -1283.84 | AJ16: -1290.26 | AK16: -1296.71 | AL16: -1303.19 | AM16: -1309.71 | AN16: =SUM(D16:O16) -> 0 | AO16: =SUM(P16:AA16) -> 0 | AP16: =SUM(AB16:AM16) -> -9032.26
B17: Liquidación IVA (informativo) | D17: =D11*0.21-D12*0.21 -> 67.290233 | E17: =E11*0.21-E12*0.21 -> -438.13983 | F17: =F11*0.21-F12*0.21 -> -116.98057 | G17: =G11*0.21-G12*0.21 -> -171.79498 | H17: =H11*0.21-H12*0.21 -> -38.251564 | I17: =I11*0.21-I12*0.21 -> -53.868915 | J17: =J11*0.21-J12*0.21 -> -124.78371 | K17: =K11*0.21-K12*0.21 -> 19.460503 | ... AM17: =AM11*0.21-AM12*0.21 -> 7502.8592 | AN17: =SUM(D17:O17) -> -470.13399 | AO17: =SUM(P17:AA17) -> 15247.093 | AP17: =SUM(AB17:AM17) -> 64837.974
B18: CASH FLOW OPERATIVO (= Net Income) | D18: =D10 -> -7605.6821 | E18: =E10 -> -6524.2811 | F18: =F10 -> -5260.3722 | G18: =G10 -> -5476.092 | H18: =H10 -> -4950.5374 | I18: =I10 -> -5261.9989 | J18: =J10 -> -5541.0811 | K18: =K10 -> -4973.414 | ... AM18: =AM10 -> 10019.112 | AN18: =SUM(D18:O18) -> -64270.693 | AO18: =SUM(P18:AA18) -> -89417.312 | AP18: =SUM(AB18:AM18) -> 34177.975
B19: ACTIVIDADES DE INVERSIÓN
B20: CAPEX (equipos, ordenadores) | D20: -5000 | E20: 0 | F20: 0 | G20: 0 | H20: 0 | I20: 0 | J20: 0 | K20: 0 | L20: 0 | M20: 0 | N20: 0 | O20: 0 | P20: -8000 | Q20: 0 | R20: 0 | S20: 0 | T20: 0 | U20: 0 | V20: 0 | W20: 0 | X20: 0 | Y20: 0 | Z20: 0 | AA20: 0 | AB20: -15000 | AC20: 0 | AD20: 0 | AE20: 0 | AF20: 0 | AG20: 0 | AH20: 0 | AI20: 0 | AJ20: 0 | AK20: 0 | AL20: 0 | AM20: 0 | AN20: =SUM(D20:O20) -> -5000 | AO20: =SUM(P20:AA20) -> -8000 | AP20: =SUM(AB20:AM20) -> -15000
B21: CASH FLOW DE INVERSIÓN | D21: =D20 -> -5000 | E21: =E20 -> 0 | F21: =F20 -> 0 | G21: =G20 -> 0 | H21: =H20 -> 0 | I21: =I20 -> 0 | J21: =J20 -> 0 | K21: =K20 -> 0 | ... AM21: =AM20 -> 0 | AN21: =SUM(D21:O21) -> -5000 | AO21: =SUM(P21:AA21) -> -8000 | AP21: =SUM(AB21:AM21) -> -15000
B22: ACTIVIDADES DE FINANCIACIÓN
B23: Equity Pre-Seed (inyección) | D23: =C7 -> 180000 | E23: 0 | F23: 0 | G23: 0 | H23: 0 | I23: 0 | J23: 0 | K23: 0 | L23: 0 | M23: 0 | N23: 0 | O23: 0 | P23: 0 | Q23: 0 | R23: 0 | S23: 0 | T23: 0 | U23: 0 | V23: 0 | W23: 0 | X23: 0 | Y23: 0 | Z23: 0 | AA23: 0 | AB23: 0 | AC23: 0 | AD23: 0 | AE23: 0 | AF23: 0 | AG23: 0 | AH23: 0 | AI23: 0 | AJ23: 0 | AK23: 0 | AL23: 0 | AM23: 0 | AN23: =SUM(D23:O23) -> 180000 | AO23: =SUM(P23:AA23) -> 0 | AP23: =SUM(AB23:AM23) -> 0
B24: Préstamo ENISA (no dilutivo) | D24: 0 | E24: 0 | F24: 0 | G24: 0 | H24: 0 | I24: =C8 -> 50000 | J24: 0 | K24: 0 | L24: 0 | M24: 0 | N24: 0 | O24: 0 | P24: 0 | Q24: 0 | R24: 0 | S24: 0 | T24: 0 | U24: 0 | V24: 0 | W24: 0 | X24: 0 | Y24: 0 | Z24: 0 | AA24: 0 | AB24: 0 | AC24: 0 | AD24: 0 | AE24: 0 | AF24: 0 | AG24: 0 | AH24: 0 | AI24: 0 | AJ24: 0 | AK24: 0 | AL24: 0 | AM24: 0 | AN24: =SUM(D24:O24) -> 50000 | AO24: =SUM(P24:AA24) -> 0 | AP24: =SUM(AB24:AM24) -> 0
B25: CASH FLOW DE FINANCIACIÓN | D25: =D23+D24+D16 -> 180000 | E25: =E23+E24+E16 -> 0 | F25: =F23+F24+F16 -> 0 | G25: =G23+G24+G16 -> 0 | H25: =H23+H24+H16 -> 0 | I25: =I23+I24+I16 -> 50000 | J25: =J23+J24+J16 -> 0 | K25: =K23+K24+K16 -> 0 | ... AM25: =AM23+AM24+AM16 -> -1309.71 | AN25: =SUM(D25:O25) -> 230000 | AO25: =SUM(P25:AA25) -> 0 | AP25: =SUM(AB25:AM25) -> -9032.26
B26: POSICIÓN DE CAJA
B27: Variación neta de caja | D27: =D18+D21+D25 -> 167394.32 | E27: =E18+E21+E25 -> -6524.2811 | F27: =F18+F21+F25 -> -5260.3722 | G27: =G18+G21+G25 -> -5476.092 | H27: =H18+H21+H25 -> -4950.5374 | I27: =I18+I21+I25 -> 44738.001 | J27: =J18+J21+J25 -> -5541.0811 | K27: =K18+K21+K25 -> -4973.414 | ... AM27: =AM18+AM21+AM25 -> 8709.4024 | AN27: =SUM(D27:O27) -> 160729.31 | AO27: =SUM(P27:AA27) -> -97417.312 | AP27: =SUM(AB27:AM27) -> 10145.715
B28: Caja inicio de mes (BOM) | D28: 0 | E28: =D29 -> 167394.32 | F28: =E29 -> 160870.04 | G28: =F29 -> 155609.66 | H28: =G29 -> 150133.57 | I28: =H29 -> 145183.04 | J28: =I29 -> 189921.04 | K28: =J29 -> 184379.96 | L28: =K29 -> 179406.54 | ... AM28: =AL29 -> 64748.307
B29: CAJA FIN DE MES (EOM) | D29: =D28+D27 -> 167394.32 | E29: =E28+E27 -> 160870.04 | F29: =F28+F27 -> 155609.66 | G29: =G28+G27 -> 150133.57 | H29: =H28+H27 -> 145183.04 | I29: =I28+I27 -> 189921.04 | J29: =J28+J27 -> 184379.96 | K29: =K28+K27 -> 179406.54 | ... AM29: =AM28+AM27 -> 73457.71 | AN29: =O29 -> 160729.31 | AO29: =AA29 -> 63311.995 | AP29: =AM29 -> 73457.71

Sheet Amortizacion
A1: Mes | B1: Fecha | C1: Cuota (Cashflow) | D1: Interés (P&L) | E1: Amort. (Balance) | F1: Deuda Pendiente
A2: AÑO 1 | B2: (Carencia)
A3: 1 | B3: 46174 | C3: 250 | D3: 250 | E3: 0 | F3: 50000
A4: 2 | B4: 46204 | C4: 250 | D4: 250 | E4: 0 | F4: 50000
A5: 3 | B5: 46235 | C5: 250 | D5: 250 | E5: 0 | F5: 50000
A6: 4 | B6: Sep-26 | C6: 250 | D6: 250 | E6: 0 | F6: 50000
A7: 5 | B7: 46296 | C7: 250 | D7: 250 | E7: 0 | F7: 50000
A8: 6 | B8: 46327 | C8: 250 | D8: 250 | E8: 0 | F8: 50000
A9: 7 | B9: Dic-26 | C9: 250 | D9: 250 | E9: 0 | F9: 50000
A10: AÑO 2 | B10: (Carencia)
A11: 43313 | B11: Ene-Nov 27 | C11: 250 | D11: 250 | E11: 0 | F11: 50000
A12: 19 | B12: Dic-27 | C12: 250 | D12: 250 | E12: 0 | F12: 50000
A13: 20-23 | B13: Ene-Abr 28 | C13: 250 | D13: 250 | E13: 0 | F13: 50000
A14: 24 | B14: May-28 | C14: 250 | D14: 250 | E14: 0 | F14: 50000
A15: AÑO 3 | B15: (Amortiz.)
A16: 25 | B16: 46905 | C16: 1521.1 | D16: 250 | E16: 1271.1 | F16: 48728.9
A17: 26 | B17: 46935 | C17: 1521.1 | D17: 243.64 | E17: 1277.45 | F17: 47451.45
A18: 27 | B18: 46966 | C18: 1521.1 | D18: 237.26 | E18: 1283.84 | F18: 46167.61
A19: 28 | B19: Sep-28 | C19: 1521.1 | D19: 230.84 | E19: 1290.26 | F19: 44877.35
A20: 29 | B20: 47027 | C20: 1521.1 | D20: 224.39 | E20: 1296.71 | F20: 43580.64
A21: 30 | B21: 47058 | C21: 1521.1 | D21: 217.9 | E21: 1303.19 | F21: 42277.45
A22: 31 | B22: Dic-28 | C22: 1521.1 | D22: 211.39 | E22: 1309.71 | F22: 40967.74
A23: 32 | B23: Ene-29 | C23: 1521.1 | D23: 204.84 | E23: 1316.26 | F23: 39651.48
A24: 33 | B24: 47150 | C24: 1521.1 | D24: 198.26 | E24: 1322.84 | F24: 38328.64
A25: 34 | B25: 47178 | C25: 1521.1 | D25: 191.64 | E25: 1329.45 | F25: 36999.19
A26: 35 | B26: 47209 | C26: 1521.1 | D26: 185 | E26: 1336.1 | F26: 35663.09
A27: 36 | B27: May-29 | C27: 1521.1 | D27: 178.32 | E27: 1342.78 | F27: 34320.31
A28: AÑO 4 | B28: (Amortiz.)
A29: 37 | B29: 47270 | C29: 1521.1 | D29: 171.6 | E29: 1349.5 | F29: 32970.81
A30: 38 | B30: 47300 | C30: 1521.1 | D30: 164.85 | E30: 1356.24 | F30: 31614.57
A31: 39 | B31: 47331 | C31: 1521.1 | D31: 158.07 | E31: 1363.02 | F31: 30251.54
A32: 40 | B32: Sep-29 | C32: 1521.1 | D32: 151.26 | E32: 1369.84 | F32: 28881.7
A33: 41 | B33: 47392 | C33: 1521.1 | D33: 144.41 | E33: 1376.69 | F33: 27505.02
A34: 42 | B34: 47423 | C34: 1521.1 | D34: 137.53 | E34: 1383.57 | F34: 26121.44
A35: 43 | B35: Dic-29 | C35: 1521.1 | D35: 130.61 | E35: 1390.49 | F35: 24730.95
A36: 44 | B36: Ene-30 | C36: 1521.1 | D36: 123.65 | E36: 1397.44 | F36: 23333.51
A37: 45 | B37: 10990 | C37: 1521.1 | D37: 116.67 | E37: 1404.43 | F37: 21929.08
A38: 46 | B38: 11018 | C38: 1521.1 | D38: 109.65 | E38: 1411.45 | F38: 20517.63
A39: 47 | B39: 11049 | C39: 1521.1 | D39: 102.59 | E39: 1418.51 | F39: 19099.12
A40: 48 | B40: May-30 | C40: 1521.1 | D40: 95.5 | E40: 1425.6 | F40: 17673.52
...

Sheet KPI Dashboard
B1: TalentPact — KPI Dashboard (Resumen Anual)
B3: KPI / Métrica | C3: 2026 | D3: 2027 | E3: 2028 | F3: CAGR
B4: INGRESOS
B5: Ingreso Bruto (€) | C5: ='MODELO NORMAL'!AN39 -> 16635.94 | D5: ='MODELO NORMAL'!AO39 -> 110969.71 | E5: ='MODELO NORMAL'!AP39 -> 367575.43 | F5: =(E5/C5)^(1/2)-1 -> 3.7005596
B6: Ingreso Neto (€) | C6: ='P&L'!AN6 -> 16303.221 | D6: ='P&L'!AO6 -> 108750.32 | E6: ='P&L'!AP6 -> 360223.92 | F6: =(E6/C6)^(1/2)-1 -> 3.7005596
B7: CLIENTES
B8: Empresas EOM (Total) | C8: ='MODELO NORMAL'!O27 -> 24 | D8: ='MODELO NORMAL'!AA27 -> 129 | E8: ='MODELO NORMAL'!AM27 -> 284 | F8: =(E8/C8)^(1/2)-1 -> 2.4399612
B9: Candidatos EOM (Total) | C9: ='MODELO NORMAL'!O32 -> 746 | D9: ='MODELO NORMAL'!AA32 -> 3607 | E9: ='MODELO NORMAL'!AM32 -> 8746 | F9: =(E9/C9)^(1/2)-1 -> 2.4240124
B10: RENTABILIDAD
B11: EBITDA (€) | C11: ='P&L'!AN17 -> -62520.693 | D11: ='P&L'!AO17 -> -86395.699 | E11: ='P&L'!AP17 -> 45167.156 | F11: N/A
B12: Net Income (€) | C12: ='P&L'!AN21 -> -64270.693 | D12: ='P&L'!AO21 -> -89417.312 | E12: ='P&L'!AP21 -> 34177.975 | F12: N/A
B13: COSTES
B14: Total COGS (€) | C14: =SUM('COGS & SG&A'!D32:O32) -> 1062.914 | D14: =SUM('COGS & SG&A'!P32:AA32) -> 7262.015 | E14: =SUM('COGS & SG&A'!AB32:AM32) -> 22427.761 | F14: =(E14/C14)^(1/2)-1 -> 3.5935019
B15: Total SG&A (€) | C15: =SUM('COGS & SG&A'!D48:O48) -> 77761 | D15: =SUM('COGS & SG&A'!P48:AA48) -> 187884 | E15: =SUM('COGS & SG&A'!AB48:AM48) -> 292629 | F15: =(E15/C15)^(1/2)-1 -> 0.93989294
B16: Total Salarios (€) | C16: ='COGS & SG&A'!AN34 -> 57600 | D16: ='COGS & SG&A'!AO34 -> 146400 | E16: ='COGS & SG&A'!AP34 -> 210000 | F16: =(E16/C16)^(1/2)-1 -> 0.90940654
B17: CAJA
B18: Caja fin de año (€) | C18: =Cashflow!O29 -> 160729.31 | D18: =Cashflow!AA29 -> 63311.995 | E18: =Cashflow!AM29 -> 73457.71 | F18: N/A

Sheet Balance
A1: TALENTPACT — BALANCE DE SITUACIÓN
A2: ACTIVO | B2: 31-Dic-2026 | C2: 31-Dic-2027 | D2: 31-Dic-2028 | F2: PASIVO Y PATRIMONIO NETO | G2: 31-Dic-2026 | H2: 31-Dic-2027 | I2: 31-Dic-2028
A3: ACTIVO NO CORRIENTE | F3: PATRIMONIO NETO
A4: Inmovilizado Material (Equipos) | B4: =-Cashflow!AN20 -> 5000 | C4: =B4+(-Cashflow!AO20) -> 13000 | D4: =C4+(-Cashflow!AP20) -> 28000 | F4: Capital Social (Pre-Seed) | G4: =Cashflow!C7 -> 180000 | H4: =G4 -> 180000 | I4: =H4 -> 180000
A5: TOTAL ACTIVO NO CORRIENTE | B5: =B4 -> 5000 | C5: =C4 -> 13000 | D5: =D4 -> 28000 | F5: Reservas (Pérdidas Acumuladas) | G5: 0 | H5: ='P&L'!AN21 -> -64270.693 | I5: =H5+'P&L'!AO21 -> -153688.01
A6: ACTIVO CORRIENTE | F6: Resultado del Ejercicio | G6: ='P&L'!AN21 -> -64270.693 | H6: ='P&L'!AO21 -> -89417.312 | I6: ='P&L'!AP21 -> 34177.975
A7: Tesorería y Equivalentes | B7: =Cashflow!O29 -> 160729.31 | C7: =Cashflow!AA29 -> 63311.995 | D7: =Cashflow!AM29 -> 73457.71 | F7: TOTAL PATRIMONIO NETO | G7: =SUM(G4:G6) -> 115729.31 | H7: =SUM(H4:H6) -> 26311.995 | I7: =SUM(I4:I6) -> 60489.97
A8: TOTAL ACTIVO CORRIENTE | B8: =B7 -> 160729.31 | C8: =C7 -> 63311.995 | D8: =D7 -> 73457.71 | F8: PASIVO (Deuda ENISA)
